Workbook
Name NativeTimeline_OrderDate: #N/A
Name Slicer_Country: #N/A

Sheet DateTable
A1: Date | B1: Year | C1: Month | D1: Day | E1: Week of Year
A2: 42736 | B2: 2017 | C2: 1 | D2: 1 | E2: 1
A3: 42737 | B3: 2017 | C3: 1 | D3: 2 | E3: 2
A4: 42738 | B4: 2017 | C4: 1 | D4: 3 | E4: 2
A5: 42739 | B5: 2017 | C5: 1 | D5: 4 | E5: 2
A6: 42740 | B6: 2017 | C6: 1 | D6: 5 | E6: 2
A7: 42741 | B7: 2017 | C7: 1 | D7: 6 | E7: 2
A8: 42742 | B8: 2017 | C8: 1 | D8: 7 | E8: 2
A9: 42743 | B9: 2017 | C9: 1 | D9: 8 | E9: 2
A10: 42744 | B10: 2017 | C10: 1 | D10: 9 | E10: 3
A11: 42745 | B11: 2017 | C11: 1 | D11: 10 | E11: 3
A12: 42746 | B12: 2017 | C12: 1 | D12: 11 | E12: 3
A13: 42747 | B13: 2017 | C13: 1 | D13: 12 | E13: 3
... A366: 43100 | B366: 2017 | C366: 12 | D366: 31 | E366: 53

Sheet Dashboard
A1: 3588358.3 | B1: 14975 | C1: 9999 | D1: 1514343.3 | E1: 2074015
A2: Total Sales | B2: Total Quantity Total Order Total Profit Total Cost | C2: Total Orders | D2: Total Profit | E2: Total Cost

Sheet Top 5 Products
A3: Product | B3: Total Orders
A4: Water Bottle - 30 oz. | B4: 930
A5: Patch Kit/8 Patches | B5: 664
A6: Mountain Tire Tube | B6: 595
A7: Sport-100 Helmet, Red | B7: 484
A8: Road Tire Tube | B8: 479

Sheet Bottom 5 products
A3: Product | B3: Total Orders
A4: Touring-3000 Yellow, 54 | B4: 6
A5: Touring-3000 Blue, 50 | B5: 7
A6: Mountain-500 Silver, 44 | B6: 9
A7: Mountain-500 Silver, 42 | B7: 7
A8: Mountain-500 Silver, 40 | B8: 9
A9: Mountain-500 Black, 42 | B9: 9

Sheet Country
A3: Country | B3: Sum of TotalProfit | C3: TotalSales | D3: TotalOrder
A4: Australia | B4: 401280.54 | C4: 967648.02 | D4: 2539
A5: Southwest | B5: 329066.71 | C5: 771893.6 | D5: 2491
A6: Northwest | B6: 190066.24 | C6: 440243.26 | D6: 1751
A7: Germany | B7: 180490.54 | C7: 430826.35 | D7: 1096
A8: United Kingdom | B8: 173246.46 | C8: 408291.97 | D8: 1285
A9: France | B9: 141758.46 | C9: 334507.53 | D9: 1068

Sheet Most Profitable Product
A3: Product | B3: Sum of TotalProfit
A4: Mountain-200 Silver, 38 | B4: 105845.57

Sheet Monthly Sales Trend
A3: Months | B3: Sum of TotalSales
A4: 2017 | B4: 1046456.3
A5: Jan | B5: 56019.207
A6: Feb | B6: 65502.737
A7: Mar | B7: 89724.416
A8: Apr | B8: 97108.011
A9: May | B9: 101706.29
A10: Jun | B10: 79253.625
A11: Jul | B11: 68000.185
A12: Aug | B12: 108139.73
A13: Sept | B13: 84082.168
A14: Oct | B14: 109258.37
A15: Nov | B15: 85868.206
A16: Dec | B16: 101793.33

Sheet Weekly Revenue
A3: Row Labels | B3: Sum of TotalSales
A4: 2017 | B4: 1046456.3
A5: Jan | B5: 56019.207
A6: 42745 | B6: 5142.333
A7: 42746 | B7: 16470.312
A8: 42747 | B8: 34406.561
A9: Feb | B9: 65502.737
A10: 42776 | B10: 17435.821
A11: 42777 | B11: 13034.38
A12: 42778 | B12: 35032.536
A13: Mar | B13: 89724.416
A14: 42803 | B14: 573.6342
A15: 42804 | B15: 6061.5424
A16: 42805 | B16: 31350.473
A17: 42806 | B17: 51738.767
A18: Apr | B18: 97108.011
A19: 42834 | B19: 123.3204
A20: 42835 | B20: 11782.028
A21: 42836 | B21: 45947.354
A22: 42837 | B22: 39255.308
A23: May | B23: 101706.29
A24: 42864 | B24: 273.94
A25: 42865 | B25: 18830.863
A26: 42866 | B26: 24919.117
A27: 42867 | B27: 57682.366
A28: Jun | B28: 79253.625
A29: 42895 | B29: 154.87
A30: 42896 | B30: 21325.122
A31: 42897 | B31: 35578.776
A32: 42898 | B32: 22194.857
A33: Jul | B33: 68000.185
A34: 42925 | B34: 28.54
A35: 42926 | B35: 11264.372
A36: 42927 | B36: 30912.295
A37: 42928 | B37: 25794.979
A38: Aug | B38: 108139.73
A39: 42956 | B39: 966.5168
A40: 42957 | B40: 9581.7928
A41: 42958 | B41: 45672.598
A42: 42959 | B42: 51918.82
...

Sheet Sales
A1: StockDate | B1: OrderNumber | C1: ProductKey | D1: CustomerKey | E1: TerritoryKey | F1: OrderLineItem | G1: OrderQuantity | H1: OrderDate | I1: Country | J1: ProductCost | K1: ProductPrice | L1: TotalSales | M1: TotalQuantity | N1: TotalOrder | O1: TotalProfit | P1: TotalCost | Q1: ProductName
A2: 37631 | B2: SO61305 | C2: 583 | D2: 20236 | E2: 9 | F2: 1 | G2: 1 | H2: 42745 | I2: =VLOOKUP(Sales[[#This Row],[TerritoryKey]], Territories[], 2, FALSE) -> Australia | J2: =_xlfn.XLOOKUP(Sales[[#This Row],[ProductKey]], Products!$A:$A, Products!$J:$J) -> 1082.51 | K2: =_xlfn.XLOOKUP(Sales[[#This Row],[ProductKey]], Products!$A:$A, Products!$K:$K) -> 1700.99 | L2: =Sales[[#This Row],[ProductPrice]]*Sales[[#This Row],[OrderQuantity]] -> 1700.99 | M2: =Sales[[#This Row],[OrderQuantity]] -> 1 | N2: =1 -> 1 | O2: =Sales[[#This Row],[TotalSales]]-Sales[[#This Row],[TotalCost]] -> 618.48 | P2: =Sales[[#This Row],[ProductCost]]*Sales[[#This Row],[OrderQuantity]] -> 1082.51 | Q2: =VLOOKUP(Sales[[#This Row],[ProductKey]], Products!$A$2:$D$1000, 4, FALSE) -> Road-350-W Yellow, 48
A3: 37782 | B3: SO61307 | C3: 582 | D3: 20260 | E3: 9 | F3: 1 | G3: 1 | H3: 42896 | I3: =VLOOKUP(Sales[[#This Row],[TerritoryKey]], Territories[], 2, FALSE) -> Australia | J3: =_xlfn.XLOOKUP(Sales[[#This Row],[ProductKey]], Products!$A:$A, Products!$J:$J) -> 1082.51 | K3: =_xlfn.XLOOKUP(Sales[[#This Row],[ProductKey]], Products!$A:$A, Products!$K:$K) -> 1700.99 | L3: =Sales[[#This Row],[ProductPrice]]*Sales[[#This Row],[OrderQuantity]] -> 1700.99 | M3: =Sales[[#This Row],[OrderQuantity]] -> 1 | N3: =1 -> 1 | O3: =Sales[[#This Row],[TotalSales]]-Sales[[#This Row],[TotalCost]] -> 618.48 | P3: =Sales[[#This Row],[ProductCost]]*Sales[[#This Row],[OrderQuantity]] -> 1082.51 | Q3: =VLOOKUP(Sales[[#This Row],[ProductKey]], Products!$A$2:$D$1000, 4, FALSE) -> Road-350-W Yellow, 44
A4: 37964 | B4: SO61306 | C4: 580 | D4: 23431 | E4: 9 | F4: 1 | G4: 1 | H4: 43078 | I4: =VLOOKUP(Sales[[#This Row],[TerritoryKey]], Territories[], 2, FALSE) -> Australia | J4: =_xlfn.XLOOKUP(Sales[[#This Row],[ProductKey]], Products!$A:$A, Products!$J:$J) -> 1082.51 | K4: =_xlfn.XLOOKUP(Sales[[#This Row],[ProductKey]], Products!$A:$A, Products!$K:$K) -> 1700.99 | L4: =Sales[[#This Row],[ProductPrice]]*Sales[[#This Row],[OrderQuantity]] -> 1700.99 | M4: =Sales[[#This Row],[OrderQuantity]] -> 1 | N4: =1 -> 1 | O4: =Sales[[#This Row],[TotalSales]]-Sales[[#This Row],[TotalCost]] -> 618.48 | P4: =Sales[[#This Row],[ProductCost]]*Sales[[#This Row],[OrderQuantity]] -> 1082.51 | Q4: =VLOOKUP(Sales[[#This Row],[ProductKey]], Products!$A$2:$D$1000, 4, FALSE) -> Road-350-W Yellow, 40
A5: 37967 | B5: SO61368 | C5: 576 | D5: 11904 | E5: 9 | F5: 1 | G5: 1 | H5: 43081 | I5: =VLOOKUP(Sales[[#This Row],[TerritoryKey]], Territories[], 2, FALSE) -> Australia | J5: =_xlfn.XLOOKUP(Sales[[#This Row],[ProductKey]], Products!$A:$A, Products!$J:$J) -> 1481.9379 | K5: =_xlfn.XLOOKUP(Sales[[#This Row],[ProductKey]], Products!$A:$A, Products!$K:$K) -> 2384.07 | L5: =Sales[[#This Row],[ProductPrice]]*Sales[[#This Row],[OrderQuantity]] -> 2384.07 | M5: =Sales[[#This Row],[OrderQuantity]] -> 1 | N5: =1 -> 1 | O5: =Sales[[#This Row],[TotalSales]]-Sales[[#This Row],[TotalCost]] -> 902.1321 | P5: =Sales[[#This Row],[ProductCost]]*Sales[[#This Row],[OrderQuantity]] -> 1481.9379 | Q5: =VLOOKUP(Sales[[#This Row],[ProductKey]], Products!$A$2:$D$1000, 4, FALSE) -> Touring-1000 Blue, 60
A6: 37783 | B6: SO61321 | C6: 235 | D6: 14319 | E6: 9 | F6: 1 | G6: 1 | H6: 42897 | I6: =VLOOKUP(Sales[[#This Row],[TerritoryKey]], Territories[], 2, FALSE) -> Australia | J6: =_xlfn.XLOOKUP(Sales[[#This Row],[ProductKey]], Products!$A:$A, Products!$J:$J) -> 31.7244 | K6: =_xlfn.XLOOKUP(Sales[[#This Row],[ProductKey]], Products!$A:$A, Products!$K:$K) -> 48.0673 | L6: =Sales[[#This Row],[ProductPrice]]*Sales[[#This Row],[OrderQuantity]] -> 48.0673 | M6: =Sales[[#This Row],[OrderQuantity]] -> 1 | N6: =1 -> 1 | O6: =Sales[[#This Row],[TotalSales]]-Sales[[#This Row],[TotalCost]] -> 16.3429 | P6: =Sales[[#This Row],[ProductCost]]*Sales[[#This Row],[OrderQuantity]] -> 31.7244 | Q6: =VLOOKUP(Sales[[#This Row],[ProductKey]], Products!$A$2:$D$1000, 4, FALSE) -> Long-Sleeve Logo Jersey, XL
A7: 37721 | B7: SO61420 | C7: 362 | D7: 13122 | E7: 9 | F7: 1 | G7: 1 | H7: 42835 | I7: =VLOOKUP(Sales[[#This Row],[TerritoryKey]], Territories[], 2, FALSE) -> Australia | J7: =_xlfn.XLOOKUP(Sales[[#This Row],[ProductKey]], Products!$A:$A, Products!$J:$J) -> 1105.81 | K7: =_xlfn.XLOOKUP(Sales[[#This Row],[ProductKey]], Products!$A:$A, Products!$K:$K) -> 2049.0982 | L7: =Sales[[#This Row],[ProductPrice]]*Sales[[#This Row],[OrderQuantity]] -> 2049.0982 | M7: =Sales[[#This Row],[OrderQuantity]] -> 1 | N7: =1 -> 1 | O7: =Sales[[#This Row],[TotalSales]]-Sales[[#This Row],[TotalCost]] -> 943.2882 | P7: =Sales[[#This Row],[ProductCost]]*Sales[[#This Row],[OrderQuantity]] -> 1105.81 | Q7: =VLOOKUP(Sales[[#This Row],[ProductKey]], Products!$A$2:$D$1000, 4, FALSE) -> Mountain-200 Black, 46
A8: 37753 | B8: SO61419 | C8: 387 | D8: 24484 | E8: 9 | F8: 1 | G8: 1 | H8: 42867 | I8: =VLOOKUP(Sales[[#This Row],[TerritoryKey]], Territories[], 2, FALSE) -> Australia | J8: =_xlfn.XLOOKUP(Sales[[#This Row],[ProductKey]], Products!$A:$A, Products!$J:$J) -> 605.6492 | K8: =_xlfn.XLOOKUP(Sales[[#This Row],[ProductKey]], Products!$A:$A, Products!$K:$K) -> 1000.4375 | L8: =Sales[[#This Row],[ProductPrice]]*Sales[[#This Row],[OrderQuantity]] -> 1000.4375 | M8: =Sales[[#This Row],[OrderQuantity]] -> 1 | N8: =1 -> 1 | O8: =Sales[[#This Row],[TotalSales]]-Sales[[#This Row],[TotalCost]] -> 394.7883 | P8: =Sales[[#This Row],[ProductCost]]*Sales[[#This Row],[OrderQuantity]] -> 605.6492 | Q8: =VLOOKUP(Sales[[#This Row],[ProductKey]], Products!$A$2:$D$1000, 4, FALSE) -> Road-550-W Yellow, 44
A9: 37876 | B9: SO61374 | C9: 215 | D9: 13046 | E9: 9 | F9: 1 | G9: 1 | H9: 42990 | I9: =VLOOKUP(Sales[[#This Row],[TerritoryKey]], Territories[], 2, FALSE) -> Australia | J9: =_xlfn.XLOOKUP(Sales[[#This Row],[ProductKey]], Products!$A:$A, Products!$J:$J) -> 12.0278 | K9: =_xlfn.XLOOKUP(Sales[[#This Row],[ProductKey]], Products!$A:$A, Products!$K:$K) -> 33.6442 | L9: =Sales[[#This Row],[ProductPrice]]*Sales[[#This Row],[OrderQuantity]] -> 33.6442 | M9: =Sales[[#This Row],[OrderQuantity]] -> 1 | N9: =1 -> 1 | O9: =Sales[[#This Row],[TotalSales]]-Sales[[#This Row],[TotalCost]] -> 21.6164 | P9: =Sales[[#This Row],[ProductCost]]*Sales[[#This Row],[OrderQuantity]] -> 12.0278 | Q9: =VLOOKUP(Sales[[#This Row],[ProductKey]], Products!$A$2:$D$1000, 4, FALSE) -> Sport-100 Helmet, Black
A10: 37664 | B10: SO61417 | C10: 387 | D10: 17734 | E10: 9 | F10: 1 | G10: 1 | H10: 42778 | I10: =VLOOKUP(Sales[[#This Row],[TerritoryKey]], Territories[], 2, FALSE) -> Australia | J10: =_xlfn.XLOOKUP(Sales[[#This Row],[ProductKey]], Products!$A:$A, Products!$J:$J) -> 605.6492 | K10: =_xlfn.XLOOKUP(Sales[[#This Row],[ProductKey]], Products!$A:$A, Products!$K:$K) -> 1000.4375 | L10: =Sales[[#This Row],[ProductPrice]]*Sales[[#This Row],[OrderQuantity]] -> 1000.4375 | M10: =Sales[[#This Row],[OrderQuantity]] -> 1 | N10: =1 -> 1 | O10: =Sales[[#This Row],[TotalSales]]-Sales[[#This Row],[TotalCost]] -> 394.7883 | P10: =Sales[[#This Row],[ProductCost]]*Sales[[#This Row],[OrderQuantity]] -> 605.6492 | Q10: =VLOOKUP(Sales[[#This Row],[ProductKey]], Products!$A$2:$D$1000, 4, FALSE) -> Road-550-W Yellow, 44
A11: 37814 | B11: SO61435 | C11: 488 | D11: 17250 | E11: 9 | F11: 1 | G11: 1 | H11: 42928 | I11: =VLOOKUP(Sales[[#This Row],[TerritoryKey]], Territories[], 2, FALSE) -> Australia | J11: =_xlfn.XLOOKUP(Sales[[#This Row],[ProductKey]], Products!$A:$A, Products!$J:$J) -> 41.5723 | K11: =_xlfn.XLOOKUP(Sales[[#This Row],[ProductKey]], Products!$A:$A, Products!$K:$K) -> 53.99 | L11: =Sales[[#This Row],[ProductPrice]]*Sales[[#This Row],[OrderQuantity]] -> 53.99 | M11: =Sales[[#This Row],[OrderQuantity]] -> 1 | N11: =1 -> 1 | O11: =Sales[[#This Row],[TotalSales]]-Sales[[#This Row],[TotalCost]] -> 12.4177 | P11: =Sales[[#This Row],[ProductCost]]*Sales[[#This Row],[OrderQuantity]] -> 41.5723 | Q11: =VLOOKUP(Sales[[#This Row],[ProductKey]], Products!$A$2:$D$1000, 4, FALSE) -> Short-Sleeve Classic Jersey, S
A12: 37935 | B12: SO61471 | C12: 389 | D12: 17730 | E12: 9 | F12: 1 | G12: 1 | H12: 43049 | I12: =VLOOKUP(Sales[[#This Row],[TerritoryKey]], Territories[], 2, FALSE) -> Australia | J12: =_xlfn.XLOOKUP(Sales[[#This Row],[ProductKey]], Products!$A:$A, Products!$J:$J) -> 605.6492 | K12: =_xlfn.XLOOKUP(Sales[[#This Row],[ProductKey]], Products!$A:$A, Products!$K:$K) -> 1000.4375 | L12: =Sales[[#This Row],[ProductPrice]]*Sales[[#This Row],[OrderQuantity]] -> 1000.4375 | M12: =Sales[[#This Row],[OrderQuantity]] -> 1 | N12: =1 -> 1 | O12: =Sales[[#This Row],[TotalSales]]-Sales[[#This Row],[TotalCost]] -> 394.7883 | P12: =Sales[[#This Row],[ProductCost]]*Sales[[#This Row],[OrderQuantity]] -> 605.6492 | Q12: =VLOOKUP(Sales[[#This Row],[ProductKey]], Products!$A$2:$D$1000, 4, FALSE) -> Road-550-W Yellow, 48
A13: 37690 | B13: SO61473 | C13: 358 | D13: 13135 | E13: 9 | F13: 1 | G13: 1 | H13: 42804 | I13: =VLOOKUP(Sales[[#This Row],[TerritoryKey]], Territories[], 2, FALSE) -> Australia | J13: =_xlfn.XLOOKUP(Sales[[#This Row],[ProductKey]], Products!$A:$A, Products!$J:$J) -> 1105.81 | K13: =_xlfn.XLOOKUP(Sales[[#This Row],[ProductKey]], Products!$A:$A, Products!$K:$K) -> 2049.0982 | L13: =Sales[[#This Row],[ProductPrice]]*Sales[[#This Row],[OrderQuantity]] -> 2049.0982 | M13: =Sales[[#This Row],[OrderQuantity]] -> 1 | N13: =1 -> 1 | O13: =Sales[[#This Row],[TotalSales]]-Sales[[#This Row],[TotalCost]] -> 943.2882 | P13: =Sales[[#This Row],[ProductCost]]*Sales[[#This Row],[OrderQuantity]] -> 1105.81 | Q13: =VLOOKUP(Sales[[#This Row],[ProductKey]], Products!$A$2:$D$1000, 4, FALSE) -> Mountain-200 Black, 38
... A11697: 38202 | B11697: SO73780 | C11697: 232 | D11697: 14719 | E11697: 7 | F11697: 6 | G11697: 1 | H11697: 43315 | I11697: =VLOOKUP(Sales[[#This Row],[TerritoryKey]], Territories[], 2, FALSE) -> France | J11697: =_xlfn.XLOOKUP(Sales[[#This Row],[ProductKey]], Products!$A:$A, Products!$J:$J) -> 31.7244 | K11697: =_xlfn.XLOOKUP(Sales[[#This Row],[ProductKey]], Products!$A:$A, Products!$K:$K) -> 48.0673 | L11697: =Sales[[#This Row],[ProductPrice]]*Sales[[#This Row],[OrderQuantity]] -> 48.0673 | M11697: =Sales[[#This Row],[OrderQuantity]] -> 1 | N11697: =1 -> 1 | O11697: =Sales[[#This Row],[TotalSales]]-Sales[[#This Row],[TotalCost]] -> 16.3429 | P11697: =Sales[[#This Row],[ProductCost]]*Sales[[#This Row],[OrderQuantity]] -> 31.7244 | Q11697: =VLOOKUP(Sales[[#This Row],[ProductKey]], Products!$A$2:$D$1000, 4, FALSE) -> Long-Sleeve Logo Jersey, L
L11698: =_xlfn.AGGREGATE(9,6,L2:L10000) -> 3588358.3 | M11698: =_xlfn.AGGREGATE(9,6,M2:M10000) -> 14975 | N11698: =_xlfn.AGGREGATE(9,6,N2:N10000) -> 9999 | O11698: =_xlfn.AGGREGATE(9,6,O2:O10000) -> 1514343.3 | P11698: =_xlfn.AGGREGATE(9,6,P2:P10000) -> 2074015

Sheet Products
A1: ProductKey | B1: ProductSubcategoryKey | C1: ProductSKU | D1: ProductName | E1: ModelName | F1: ProductDescription | G1: ProductColor | H1: ProductSize | I1: ProductStyle | J1: ProductCost | K1: ProductPrice
A2: 214 | B2: 31 | C2: HL-U509-R | D2: Sport-100 Helmet, Red | E2: Sport-100 | F2: Universal fit, well-vented, lightweight , snap-on visor. | G2: Red | H2: 0 | I2: 0 | J2: 13.0863 | K2: 34.99
A3: 215 | B3: 31 | C3: HL-U509 | D3: Sport-100 Helmet, Black | E3: Sport-100 | F3: Universal fit, well-vented, lightweight , snap-on visor. | G3: Black | H3: 0 | I3: 0 | J3: 12.0278 | K3: 33.6442
A4: 220 | B4: 31 | C4: HL-U509-B | D4: Sport-100 Helmet, Blue | E4: Sport-100 | F4: Universal fit, well-vented, lightweight , snap-on visor. | G4: Blue | H4: 0 | I4: 0 | J4: 12.0278 | K4: 33.6442
A5: 223 | B5: 19 | C5: CA-1098 | D5: AWC Logo Cap | E5: Cycling Cap | F5: Traditional style with a flip-up brim; one-size fits all. | G5: Multi | H5: 0 | I5: U | J5: 5.7052 | K5: 8.6442
A6: 391 | B6: 10 | C6: FK-1639 | D6: LL Fork | E6: LL Fork | F6: Stout design absorbs shock and offers more precise steering. | G6: NA | H6: 0 | I6: 0 | J6: 65.8097 | K6: 148.22
A7: 392 | B7: 10 | C7: FK-5136 | D7: ML Fork | E7: ML Fork | F7: Composite road fork with an aluminum steerer tube. | G7: NA | H7: 0 | I7: 0 | J7: 77.9176 | K7: 175.49
A8: 393 | B8: 10 | C8: FK-9939 | D8: HL Fork | E8: HL Fork | F8: High-performance carbon road fork with curved legs. | G8: NA | H8: 0 | I8: 0 | J8: 101.8936 | K8: 229.49
A9: 394 | B9: 11 | C9: HS-0296 | D9: LL Headset | E9: LL Headset | F9: Threadless headset provides quality at an economical price. | G9: NA | H9: 0 | I9: 0 | J9: 15.1848 | K9: 34.2
A10: 395 | B10: 11 | C10: HS-2451 | D10: ML Headset | E10: ML Headset | F10: Sealed cartridge keeps dirt out. | G10: NA | H10: 0 | I10: 0 | J10: 45.4168 | K10: 102.29
A11: 396 | B11: 11 | C11: HS-3479 | D11: HL Headset | E11: HL Headset | F11: High-quality 1" threadless headset with a grease port for quick lubrication. | G11: NA | H11: 0 | I11: 0 | J11: 55.3801 | K11: 124.73
A12: 397 | B12: 4 | C12: HB-M243 | D12: LL Mountain Handlebars | E12: LL Mountain Handlebars | F12: All-purpose bar for on or off-road. | G12: NA | H12: 0 | I12: 0 | J12: 17.978 | K12: 40.4909
A13: 399 | B13: 4 | C13: HB-M763 | D13: ML Mountain Handlebars | E13: ML Mountain Handlebars | F13: Tough aluminum alloy bars for downhill. | G13: NA | H13: 0 | I13: 0 | J13: 24.9932 | K13: 56.2909
... A294: 606 | B294: 2 | C294: BK-R19B-52 | D294: Road-750 Black, 52 | E294: Road-750 | F294: Entry level adult bike; offers a comfortable ride cross-country or down the block. Quick-release hubs and rims. | G294: Black | H294: 52 | I294: U | J294: 343.6496 | K294: 539.99

Sheet Territories
A1: SalesTerritoryKey | B1: Region | C1: Country | D1: Continent
A2: 1 | B2: Northwest | C2: United States | D2: North America
A3: 2 | B3: Northeast | C3: United States | D3: North America
A4: 3 | B4: Central | C4: United States | D4: North America
A5: 4 | B5: Southwest | C5: United States | D5: North America
A6: 5 | B6: Southeast | C6: United States | D6: North America
A7: 6 | B7: Canada | C7: Canada | D7: North America
A8: 7 | B8: France | C8: France | D8: Europe
A9: 8 | B9: Germany | C9: Germany | D9: Europe
A10: 9 | B10: Australia | C10: Australia | D10: Pacific
A11: 10 | B11: United Kingdom | C11: United Kingdom | D11: Europe
